{
 "cells": [
  {
   "cell_type": "code",
   "execution_count": 1,
   "id": "851f5e05-7ba6-421d-b3ab-abe0bd4f6ab1",
   "metadata": {},
   "outputs": [
    {
     "name": "stderr",
     "output_type": "stream",
     "text": [
      "\n",
      "A module that was compiled using NumPy 1.x cannot be run in\n",
      "NumPy 2.2.4 as it may crash. To support both 1.x and 2.x\n",
      "versions of NumPy, modules must be compiled with NumPy 2.0.\n",
      "Some module may need to rebuild instead e.g. with 'pybind11>=2.12'.\n",
      "\n",
      "If you are a user of the module, the easiest solution will be to\n",
      "downgrade to 'numpy<2' or try to upgrade the affected module.\n",
      "We expect that some modules will need time to support NumPy 2.\n",
      "\n",
      "Traceback (most recent call last):  File \"<frozen runpy>\", line 198, in _run_module_as_main\n",
      "  File \"<frozen runpy>\", line 88, in _run_code\n",
      "  File \"/home/codespace/.local/lib/python3.12/site-packages/ipykernel_launcher.py\", line 18, in <module>\n",
      "    app.launch_new_instance()\n",
      "  File \"/home/codespace/.local/lib/python3.12/site-packages/traitlets/config/application.py\", line 1075, in launch_instance\n",
      "    app.start()\n",
      "  File \"/home/codespace/.local/lib/python3.12/site-packages/ipykernel/kernelapp.py\", line 739, in start\n",
      "    self.io_loop.start()\n",
      "  File \"/home/codespace/.local/lib/python3.12/site-packages/tornado/platform/asyncio.py\", line 205, in start\n",
      "    self.asyncio_loop.run_forever()\n",
      "  File \"/home/codespace/anaconda3/lib/python3.12/asyncio/base_events.py\", line 639, in run_forever\n",
      "    self._run_once()\n",
      "  File \"/home/codespace/anaconda3/lib/python3.12/asyncio/base_events.py\", line 1985, in _run_once\n",
      "    handle._run()\n",
      "  File \"/home/codespace/anaconda3/lib/python3.12/asyncio/events.py\", line 88, in _run\n",
      "    self._context.run(self._callback, *self._args)\n",
      "  File \"/home/codespace/.local/lib/python3.12/site-packages/ipykernel/kernelbase.py\", line 545, in dispatch_queue\n",
      "    await self.process_one()\n",
      "  File \"/home/codespace/.local/lib/python3.12/site-packages/ipykernel/kernelbase.py\", line 534, in process_one\n",
      "    await dispatch(*args)\n",
      "  File \"/home/codespace/.local/lib/python3.12/site-packages/ipykernel/kernelbase.py\", line 437, in dispatch_shell\n",
      "    await result\n",
      "  File \"/home/codespace/.local/lib/python3.12/site-packages/ipykernel/ipkernel.py\", line 362, in execute_request\n",
      "    await super().execute_request(stream, ident, parent)\n",
      "  File \"/home/codespace/.local/lib/python3.12/site-packages/ipykernel/kernelbase.py\", line 778, in execute_request\n",
      "    reply_content = await reply_content\n",
      "  File \"/home/codespace/.local/lib/python3.12/site-packages/ipykernel/ipkernel.py\", line 449, in do_execute\n",
      "    res = shell.run_cell(\n",
      "  File \"/home/codespace/.local/lib/python3.12/site-packages/ipykernel/zmqshell.py\", line 549, in run_cell\n",
      "    return super().run_cell(*args, **kwargs)\n",
      "  File \"/home/codespace/.local/lib/python3.12/site-packages/IPython/core/interactiveshell.py\", line 3047, in run_cell\n",
      "    result = self._run_cell(\n",
      "  File \"/home/codespace/.local/lib/python3.12/site-packages/IPython/core/interactiveshell.py\", line 3102, in _run_cell\n",
      "    result = runner(coro)\n",
      "  File \"/home/codespace/.local/lib/python3.12/site-packages/IPython/core/async_helpers.py\", line 128, in _pseudo_sync_runner\n",
      "    coro.send(None)\n",
      "  File \"/home/codespace/.local/lib/python3.12/site-packages/IPython/core/interactiveshell.py\", line 3306, in run_cell_async\n",
      "    has_raised = await self.run_ast_nodes(code_ast.body, cell_name,\n",
      "  File \"/home/codespace/.local/lib/python3.12/site-packages/IPython/core/interactiveshell.py\", line 3489, in run_ast_nodes\n",
      "    if await self.run_code(code, result, async_=asy):\n",
      "  File \"/home/codespace/.local/lib/python3.12/site-packages/IPython/core/interactiveshell.py\", line 3549, in run_code\n",
      "    exec(code_obj, self.user_global_ns, self.user_ns)\n",
      "  File \"/tmp/ipykernel_25618/4080736814.py\", line 1, in <module>\n",
      "    import pandas as pd\n",
      "  File \"/home/codespace/.local/lib/python3.12/site-packages/pandas/__init__.py\", line 26, in <module>\n",
      "    from pandas.compat import (\n",
      "  File \"/home/codespace/.local/lib/python3.12/site-packages/pandas/compat/__init__.py\", line 27, in <module>\n",
      "    from pandas.compat.pyarrow import (\n",
      "  File \"/home/codespace/.local/lib/python3.12/site-packages/pandas/compat/pyarrow.py\", line 8, in <module>\n",
      "    import pyarrow as pa\n",
      "  File \"/home/codespace/anaconda3/lib/python3.12/site-packages/pyarrow/__init__.py\", line 65, in <module>\n",
      "    import pyarrow.lib as _lib\n"
     ]
    },
    {
     "ename": "ImportError",
     "evalue": "\nA module that was compiled using NumPy 1.x cannot be run in\nNumPy 2.2.4 as it may crash. To support both 1.x and 2.x\nversions of NumPy, modules must be compiled with NumPy 2.0.\nSome module may need to rebuild instead e.g. with 'pybind11>=2.12'.\n\nIf you are a user of the module, the easiest solution will be to\ndowngrade to 'numpy<2' or try to upgrade the affected module.\nWe expect that some modules will need time to support NumPy 2.\n\n",
     "output_type": "error",
     "traceback": [
      "\u001b[31m---------------------------------------------------------------------------\u001b[39m",
      "\u001b[31mImportError\u001b[39m                               Traceback (most recent call last)",
      "\u001b[36mFile \u001b[39m\u001b[32m~/.local/lib/python3.12/site-packages/numpy/core/_multiarray_umath.py:44\u001b[39m, in \u001b[36m__getattr__\u001b[39m\u001b[34m(attr_name)\u001b[39m\n\u001b[32m     39\u001b[39m     \u001b[38;5;66;03m# Also print the message (with traceback).  This is because old versions\u001b[39;00m\n\u001b[32m     40\u001b[39m     \u001b[38;5;66;03m# of NumPy unfortunately set up the import to replace (and hide) the\u001b[39;00m\n\u001b[32m     41\u001b[39m     \u001b[38;5;66;03m# error.  The traceback shouldn't be needed, but e.g. pytest plugins\u001b[39;00m\n\u001b[32m     42\u001b[39m     \u001b[38;5;66;03m# seem to swallow it and we should be failing anyway...\u001b[39;00m\n\u001b[32m     43\u001b[39m     sys.stderr.write(msg + tb_msg)\n\u001b[32m---> \u001b[39m\u001b[32m44\u001b[39m     \u001b[38;5;28;01mraise\u001b[39;00m \u001b[38;5;167;01mImportError\u001b[39;00m(msg)\n\u001b[32m     46\u001b[39m ret = \u001b[38;5;28mgetattr\u001b[39m(_multiarray_umath, attr_name, \u001b[38;5;28;01mNone\u001b[39;00m)\n\u001b[32m     47\u001b[39m \u001b[38;5;28;01mif\u001b[39;00m ret \u001b[38;5;129;01mis\u001b[39;00m \u001b[38;5;28;01mNone\u001b[39;00m:\n",
      "\u001b[31mImportError\u001b[39m: \nA module that was compiled using NumPy 1.x cannot be run in\nNumPy 2.2.4 as it may crash. To support both 1.x and 2.x\nversions of NumPy, modules must be compiled with NumPy 2.0.\nSome module may need to rebuild instead e.g. with 'pybind11>=2.12'.\n\nIf you are a user of the module, the easiest solution will be to\ndowngrade to 'numpy<2' or try to upgrade the affected module.\nWe expect that some modules will need time to support NumPy 2.\n\n"
     ]
    },
    {
     "name": "stderr",
     "output_type": "stream",
     "text": [
      "\n",
      "A module that was compiled using NumPy 1.x cannot be run in\n",
      "NumPy 2.2.4 as it may crash. To support both 1.x and 2.x\n",
      "versions of NumPy, modules must be compiled with NumPy 2.0.\n",
      "Some module may need to rebuild instead e.g. with 'pybind11>=2.12'.\n",
      "\n",
      "If you are a user of the module, the easiest solution will be to\n",
      "downgrade to 'numpy<2' or try to upgrade the affected module.\n",
      "We expect that some modules will need time to support NumPy 2.\n",
      "\n",
      "Traceback (most recent call last):  File \"<frozen runpy>\", line 198, in _run_module_as_main\n",
      "  File \"<frozen runpy>\", line 88, in _run_code\n",
      "  File \"/home/codespace/.local/lib/python3.12/site-packages/ipykernel_launcher.py\", line 18, in <module>\n",
      "    app.launch_new_instance()\n",
      "  File \"/home/codespace/.local/lib/python3.12/site-packages/traitlets/config/application.py\", line 1075, in launch_instance\n",
      "    app.start()\n",
      "  File \"/home/codespace/.local/lib/python3.12/site-packages/ipykernel/kernelapp.py\", line 739, in start\n",
      "    self.io_loop.start()\n",
      "  File \"/home/codespace/.local/lib/python3.12/site-packages/tornado/platform/asyncio.py\", line 205, in start\n",
      "    self.asyncio_loop.run_forever()\n",
      "  File \"/home/codespace/anaconda3/lib/python3.12/asyncio/base_events.py\", line 639, in run_forever\n",
      "    self._run_once()\n",
      "  File \"/home/codespace/anaconda3/lib/python3.12/asyncio/base_events.py\", line 1985, in _run_once\n",
      "    handle._run()\n",
      "  File \"/home/codespace/anaconda3/lib/python3.12/asyncio/events.py\", line 88, in _run\n",
      "    self._context.run(self._callback, *self._args)\n",
      "  File \"/home/codespace/.local/lib/python3.12/site-packages/ipykernel/kernelbase.py\", line 545, in dispatch_queue\n",
      "    await self.process_one()\n",
      "  File \"/home/codespace/.local/lib/python3.12/site-packages/ipykernel/kernelbase.py\", line 534, in process_one\n",
      "    await dispatch(*args)\n",
      "  File \"/home/codespace/.local/lib/python3.12/site-packages/ipykernel/kernelbase.py\", line 437, in dispatch_shell\n",
      "    await result\n",
      "  File \"/home/codespace/.local/lib/python3.12/site-packages/ipykernel/ipkernel.py\", line 362, in execute_request\n",
      "    await super().execute_request(stream, ident, parent)\n",
      "  File \"/home/codespace/.local/lib/python3.12/site-packages/ipykernel/kernelbase.py\", line 778, in execute_request\n",
      "    reply_content = await reply_content\n",
      "  File \"/home/codespace/.local/lib/python3.12/site-packages/ipykernel/ipkernel.py\", line 449, in do_execute\n",
      "    res = shell.run_cell(\n",
      "  File \"/home/codespace/.local/lib/python3.12/site-packages/ipykernel/zmqshell.py\", line 549, in run_cell\n",
      "    return super().run_cell(*args, **kwargs)\n",
      "  File \"/home/codespace/.local/lib/python3.12/site-packages/IPython/core/interactiveshell.py\", line 3047, in run_cell\n",
      "    result = self._run_cell(\n",
      "  File \"/home/codespace/.local/lib/python3.12/site-packages/IPython/core/interactiveshell.py\", line 3102, in _run_cell\n",
      "    result = runner(coro)\n",
      "  File \"/home/codespace/.local/lib/python3.12/site-packages/IPython/core/async_helpers.py\", line 128, in _pseudo_sync_runner\n",
      "    coro.send(None)\n",
      "  File \"/home/codespace/.local/lib/python3.12/site-packages/IPython/core/interactiveshell.py\", line 3306, in run_cell_async\n",
      "    has_raised = await self.run_ast_nodes(code_ast.body, cell_name,\n",
      "  File \"/home/codespace/.local/lib/python3.12/site-packages/IPython/core/interactiveshell.py\", line 3489, in run_ast_nodes\n",
      "    if await self.run_code(code, result, async_=asy):\n",
      "  File \"/home/codespace/.local/lib/python3.12/site-packages/IPython/core/interactiveshell.py\", line 3549, in run_code\n",
      "    exec(code_obj, self.user_global_ns, self.user_ns)\n",
      "  File \"/tmp/ipykernel_25618/4080736814.py\", line 1, in <module>\n",
      "    import pandas as pd\n",
      "  File \"/home/codespace/.local/lib/python3.12/site-packages/pandas/__init__.py\", line 49, in <module>\n",
      "    from pandas.core.api import (\n",
      "  File \"/home/codespace/.local/lib/python3.12/site-packages/pandas/core/api.py\", line 9, in <module>\n",
      "    from pandas.core.dtypes.dtypes import (\n",
      "  File \"/home/codespace/.local/lib/python3.12/site-packages/pandas/core/dtypes/dtypes.py\", line 24, in <module>\n",
      "    from pandas._libs import (\n",
      "  File \"/home/codespace/anaconda3/lib/python3.12/site-packages/pyarrow/__init__.py\", line 65, in <module>\n",
      "    import pyarrow.lib as _lib\n"
     ]
    },
    {
     "ename": "ImportError",
     "evalue": "\nA module that was compiled using NumPy 1.x cannot be run in\nNumPy 2.2.4 as it may crash. To support both 1.x and 2.x\nversions of NumPy, modules must be compiled with NumPy 2.0.\nSome module may need to rebuild instead e.g. with 'pybind11>=2.12'.\n\nIf you are a user of the module, the easiest solution will be to\ndowngrade to 'numpy<2' or try to upgrade the affected module.\nWe expect that some modules will need time to support NumPy 2.\n\n",
     "output_type": "error",
     "traceback": [
      "\u001b[31m---------------------------------------------------------------------------\u001b[39m",
      "\u001b[31mImportError\u001b[39m                               Traceback (most recent call last)",
      "\u001b[36mFile \u001b[39m\u001b[32m~/.local/lib/python3.12/site-packages/numpy/core/_multiarray_umath.py:44\u001b[39m, in \u001b[36m__getattr__\u001b[39m\u001b[34m(attr_name)\u001b[39m\n\u001b[32m     39\u001b[39m     \u001b[38;5;66;03m# Also print the message (with traceback).  This is because old versions\u001b[39;00m\n\u001b[32m     40\u001b[39m     \u001b[38;5;66;03m# of NumPy unfortunately set up the import to replace (and hide) the\u001b[39;00m\n\u001b[32m     41\u001b[39m     \u001b[38;5;66;03m# error.  The traceback shouldn't be needed, but e.g. pytest plugins\u001b[39;00m\n\u001b[32m     42\u001b[39m     \u001b[38;5;66;03m# seem to swallow it and we should be failing anyway...\u001b[39;00m\n\u001b[32m     43\u001b[39m     sys.stderr.write(msg + tb_msg)\n\u001b[32m---> \u001b[39m\u001b[32m44\u001b[39m     \u001b[38;5;28;01mraise\u001b[39;00m \u001b[38;5;167;01mImportError\u001b[39;00m(msg)\n\u001b[32m     46\u001b[39m ret = \u001b[38;5;28mgetattr\u001b[39m(_multiarray_umath, attr_name, \u001b[38;5;28;01mNone\u001b[39;00m)\n\u001b[32m     47\u001b[39m \u001b[38;5;28;01mif\u001b[39;00m ret \u001b[38;5;129;01mis\u001b[39;00m \u001b[38;5;28;01mNone\u001b[39;00m:\n",
      "\u001b[31mImportError\u001b[39m: \nA module that was compiled using NumPy 1.x cannot be run in\nNumPy 2.2.4 as it may crash. To support both 1.x and 2.x\nversions of NumPy, modules must be compiled with NumPy 2.0.\nSome module may need to rebuild instead e.g. with 'pybind11>=2.12'.\n\nIf you are a user of the module, the easiest solution will be to\ndowngrade to 'numpy<2' or try to upgrade the affected module.\nWe expect that some modules will need time to support NumPy 2.\n\n"
     ]
    },
    {
     "name": "stderr",
     "output_type": "stream",
     "text": [
      "\n",
      "A module that was compiled using NumPy 1.x cannot be run in\n",
      "NumPy 2.2.4 as it may crash. To support both 1.x and 2.x\n",
      "versions of NumPy, modules must be compiled with NumPy 2.0.\n",
      "Some module may need to rebuild instead e.g. with 'pybind11>=2.12'.\n",
      "\n",
      "If you are a user of the module, the easiest solution will be to\n",
      "downgrade to 'numpy<2' or try to upgrade the affected module.\n",
      "We expect that some modules will need time to support NumPy 2.\n",
      "\n",
      "Traceback (most recent call last):  File \"<frozen runpy>\", line 198, in _run_module_as_main\n",
      "  File \"<frozen runpy>\", line 88, in _run_code\n",
      "  File \"/home/codespace/.local/lib/python3.12/site-packages/ipykernel_launcher.py\", line 18, in <module>\n",
      "    app.launch_new_instance()\n",
      "  File \"/home/codespace/.local/lib/python3.12/site-packages/traitlets/config/application.py\", line 1075, in launch_instance\n",
      "    app.start()\n",
      "  File \"/home/codespace/.local/lib/python3.12/site-packages/ipykernel/kernelapp.py\", line 739, in start\n",
      "    self.io_loop.start()\n",
      "  File \"/home/codespace/.local/lib/python3.12/site-packages/tornado/platform/asyncio.py\", line 205, in start\n",
      "    self.asyncio_loop.run_forever()\n",
      "  File \"/home/codespace/anaconda3/lib/python3.12/asyncio/base_events.py\", line 639, in run_forever\n",
      "    self._run_once()\n",
      "  File \"/home/codespace/anaconda3/lib/python3.12/asyncio/base_events.py\", line 1985, in _run_once\n",
      "    handle._run()\n",
      "  File \"/home/codespace/anaconda3/lib/python3.12/asyncio/events.py\", line 88, in _run\n",
      "    self._context.run(self._callback, *self._args)\n",
      "  File \"/home/codespace/.local/lib/python3.12/site-packages/ipykernel/kernelbase.py\", line 545, in dispatch_queue\n",
      "    await self.process_one()\n",
      "  File \"/home/codespace/.local/lib/python3.12/site-packages/ipykernel/kernelbase.py\", line 534, in process_one\n",
      "    await dispatch(*args)\n",
      "  File \"/home/codespace/.local/lib/python3.12/site-packages/ipykernel/kernelbase.py\", line 437, in dispatch_shell\n",
      "    await result\n",
      "  File \"/home/codespace/.local/lib/python3.12/site-packages/ipykernel/ipkernel.py\", line 362, in execute_request\n",
      "    await super().execute_request(stream, ident, parent)\n",
      "  File \"/home/codespace/.local/lib/python3.12/site-packages/ipykernel/kernelbase.py\", line 778, in execute_request\n",
      "    reply_content = await reply_content\n",
      "  File \"/home/codespace/.local/lib/python3.12/site-packages/ipykernel/ipkernel.py\", line 449, in do_execute\n",
      "    res = shell.run_cell(\n",
      "  File \"/home/codespace/.local/lib/python3.12/site-packages/ipykernel/zmqshell.py\", line 549, in run_cell\n",
      "    return super().run_cell(*args, **kwargs)\n",
      "  File \"/home/codespace/.local/lib/python3.12/site-packages/IPython/core/interactiveshell.py\", line 3047, in run_cell\n",
      "    result = self._run_cell(\n",
      "  File \"/home/codespace/.local/lib/python3.12/site-packages/IPython/core/interactiveshell.py\", line 3102, in _run_cell\n",
      "    result = runner(coro)\n",
      "  File \"/home/codespace/.local/lib/python3.12/site-packages/IPython/core/async_helpers.py\", line 128, in _pseudo_sync_runner\n",
      "    coro.send(None)\n",
      "  File \"/home/codespace/.local/lib/python3.12/site-packages/IPython/core/interactiveshell.py\", line 3306, in run_cell_async\n",
      "    has_raised = await self.run_ast_nodes(code_ast.body, cell_name,\n",
      "  File \"/home/codespace/.local/lib/python3.12/site-packages/IPython/core/interactiveshell.py\", line 3489, in run_ast_nodes\n",
      "    if await self.run_code(code, result, async_=asy):\n",
      "  File \"/home/codespace/.local/lib/python3.12/site-packages/IPython/core/interactiveshell.py\", line 3549, in run_code\n",
      "    exec(code_obj, self.user_global_ns, self.user_ns)\n",
      "  File \"/tmp/ipykernel_25618/4080736814.py\", line 1, in <module>\n",
      "    import pandas as pd\n",
      "  File \"/home/codespace/.local/lib/python3.12/site-packages/pandas/__init__.py\", line 49, in <module>\n",
      "    from pandas.core.api import (\n",
      "  File \"/home/codespace/.local/lib/python3.12/site-packages/pandas/core/api.py\", line 28, in <module>\n",
      "    from pandas.core.arrays import Categorical\n",
      "  File \"/home/codespace/.local/lib/python3.12/site-packages/pandas/core/arrays/__init__.py\", line 1, in <module>\n",
      "    from pandas.core.arrays.arrow import ArrowExtensionArray\n",
      "  File \"/home/codespace/.local/lib/python3.12/site-packages/pandas/core/arrays/arrow/__init__.py\", line 5, in <module>\n",
      "    from pandas.core.arrays.arrow.array import ArrowExtensionArray\n",
      "  File \"/home/codespace/.local/lib/python3.12/site-packages/pandas/core/arrays/arrow/array.py\", line 50, in <module>\n",
      "    from pandas.core import (\n",
      "  File \"/home/codespace/.local/lib/python3.12/site-packages/pandas/core/ops/__init__.py\", line 8, in <module>\n",
      "    from pandas.core.ops.array_ops import (\n",
      "  File \"/home/codespace/.local/lib/python3.12/site-packages/pandas/core/ops/array_ops.py\", line 56, in <module>\n",
      "    from pandas.core.computation import expressions\n",
      "  File \"/home/codespace/.local/lib/python3.12/site-packages/pandas/core/computation/expressions.py\", line 21, in <module>\n",
      "    from pandas.core.computation.check import NUMEXPR_INSTALLED\n",
      "  File \"/home/codespace/.local/lib/python3.12/site-packages/pandas/core/computation/check.py\", line 5, in <module>\n",
      "    ne = import_optional_dependency(\"numexpr\", errors=\"warn\")\n",
      "  File \"/home/codespace/.local/lib/python3.12/site-packages/pandas/compat/_optional.py\", line 135, in import_optional_dependency\n",
      "    module = importlib.import_module(name)\n",
      "  File \"/home/codespace/anaconda3/lib/python3.12/importlib/__init__.py\", line 90, in import_module\n",
      "    return _bootstrap._gcd_import(name[level:], package, level)\n",
      "  File \"/home/codespace/anaconda3/lib/python3.12/site-packages/numexpr/__init__.py\", line 24, in <module>\n",
      "    from numexpr.interpreter import MAX_THREADS, use_vml, __BLOCK_SIZE1__\n"
     ]
    },
    {
     "ename": "AttributeError",
     "evalue": "_ARRAY_API not found",
     "output_type": "error",
     "traceback": [
      "\u001b[31m---------------------------------------------------------------------------\u001b[39m",
      "\u001b[31mAttributeError\u001b[39m                            Traceback (most recent call last)",
      "\u001b[31mAttributeError\u001b[39m: _ARRAY_API not found"
     ]
    },
    {
     "name": "stderr",
     "output_type": "stream",
     "text": [
      "\n",
      "A module that was compiled using NumPy 1.x cannot be run in\n",
      "NumPy 2.2.4 as it may crash. To support both 1.x and 2.x\n",
      "versions of NumPy, modules must be compiled with NumPy 2.0.\n",
      "Some module may need to rebuild instead e.g. with 'pybind11>=2.12'.\n",
      "\n",
      "If you are a user of the module, the easiest solution will be to\n",
      "downgrade to 'numpy<2' or try to upgrade the affected module.\n",
      "We expect that some modules will need time to support NumPy 2.\n",
      "\n",
      "Traceback (most recent call last):  File \"<frozen runpy>\", line 198, in _run_module_as_main\n",
      "  File \"<frozen runpy>\", line 88, in _run_code\n",
      "  File \"/home/codespace/.local/lib/python3.12/site-packages/ipykernel_launcher.py\", line 18, in <module>\n",
      "    app.launch_new_instance()\n",
      "  File \"/home/codespace/.local/lib/python3.12/site-packages/traitlets/config/application.py\", line 1075, in launch_instance\n",
      "    app.start()\n",
      "  File \"/home/codespace/.local/lib/python3.12/site-packages/ipykernel/kernelapp.py\", line 739, in start\n",
      "    self.io_loop.start()\n",
      "  File \"/home/codespace/.local/lib/python3.12/site-packages/tornado/platform/asyncio.py\", line 205, in start\n",
      "    self.asyncio_loop.run_forever()\n",
      "  File \"/home/codespace/anaconda3/lib/python3.12/asyncio/base_events.py\", line 639, in run_forever\n",
      "    self._run_once()\n",
      "  File \"/home/codespace/anaconda3/lib/python3.12/asyncio/base_events.py\", line 1985, in _run_once\n",
      "    handle._run()\n",
      "  File \"/home/codespace/anaconda3/lib/python3.12/asyncio/events.py\", line 88, in _run\n",
      "    self._context.run(self._callback, *self._args)\n",
      "  File \"/home/codespace/.local/lib/python3.12/site-packages/ipykernel/kernelbase.py\", line 545, in dispatch_queue\n",
      "    await self.process_one()\n",
      "  File \"/home/codespace/.local/lib/python3.12/site-packages/ipykernel/kernelbase.py\", line 534, in process_one\n",
      "    await dispatch(*args)\n",
      "  File \"/home/codespace/.local/lib/python3.12/site-packages/ipykernel/kernelbase.py\", line 437, in dispatch_shell\n",
      "    await result\n",
      "  File \"/home/codespace/.local/lib/python3.12/site-packages/ipykernel/ipkernel.py\", line 362, in execute_request\n",
      "    await super().execute_request(stream, ident, parent)\n",
      "  File \"/home/codespace/.local/lib/python3.12/site-packages/ipykernel/kernelbase.py\", line 778, in execute_request\n",
      "    reply_content = await reply_content\n",
      "  File \"/home/codespace/.local/lib/python3.12/site-packages/ipykernel/ipkernel.py\", line 449, in do_execute\n",
      "    res = shell.run_cell(\n",
      "  File \"/home/codespace/.local/lib/python3.12/site-packages/ipykernel/zmqshell.py\", line 549, in run_cell\n",
      "    return super().run_cell(*args, **kwargs)\n",
      "  File \"/home/codespace/.local/lib/python3.12/site-packages/IPython/core/interactiveshell.py\", line 3047, in run_cell\n",
      "    result = self._run_cell(\n",
      "  File \"/home/codespace/.local/lib/python3.12/site-packages/IPython/core/interactiveshell.py\", line 3102, in _run_cell\n",
      "    result = runner(coro)\n",
      "  File \"/home/codespace/.local/lib/python3.12/site-packages/IPython/core/async_helpers.py\", line 128, in _pseudo_sync_runner\n",
      "    coro.send(None)\n",
      "  File \"/home/codespace/.local/lib/python3.12/site-packages/IPython/core/interactiveshell.py\", line 3306, in run_cell_async\n",
      "    has_raised = await self.run_ast_nodes(code_ast.body, cell_name,\n",
      "  File \"/home/codespace/.local/lib/python3.12/site-packages/IPython/core/interactiveshell.py\", line 3489, in run_ast_nodes\n",
      "    if await self.run_code(code, result, async_=asy):\n",
      "  File \"/home/codespace/.local/lib/python3.12/site-packages/IPython/core/interactiveshell.py\", line 3549, in run_code\n",
      "    exec(code_obj, self.user_global_ns, self.user_ns)\n",
      "  File \"/tmp/ipykernel_25618/4080736814.py\", line 1, in <module>\n",
      "    import pandas as pd\n",
      "  File \"/home/codespace/.local/lib/python3.12/site-packages/pandas/__init__.py\", line 49, in <module>\n",
      "    from pandas.core.api import (\n",
      "  File \"/home/codespace/.local/lib/python3.12/site-packages/pandas/core/api.py\", line 28, in <module>\n",
      "    from pandas.core.arrays import Categorical\n",
      "  File \"/home/codespace/.local/lib/python3.12/site-packages/pandas/core/arrays/__init__.py\", line 1, in <module>\n",
      "    from pandas.core.arrays.arrow import ArrowExtensionArray\n",
      "  File \"/home/codespace/.local/lib/python3.12/site-packages/pandas/core/arrays/arrow/__init__.py\", line 5, in <module>\n",
      "    from pandas.core.arrays.arrow.array import ArrowExtensionArray\n",
      "  File \"/home/codespace/.local/lib/python3.12/site-packages/pandas/core/arrays/arrow/array.py\", line 64, in <module>\n",
      "    from pandas.core.arrays.masked import BaseMaskedArray\n",
      "  File \"/home/codespace/.local/lib/python3.12/site-packages/pandas/core/arrays/masked.py\", line 60, in <module>\n",
      "    from pandas.core import (\n",
      "  File \"/home/codespace/.local/lib/python3.12/site-packages/pandas/core/nanops.py\", line 52, in <module>\n",
      "    bn = import_optional_dependency(\"bottleneck\", errors=\"warn\")\n",
      "  File \"/home/codespace/.local/lib/python3.12/site-packages/pandas/compat/_optional.py\", line 135, in import_optional_dependency\n",
      "    module = importlib.import_module(name)\n",
      "  File \"/home/codespace/anaconda3/lib/python3.12/importlib/__init__.py\", line 90, in import_module\n",
      "    return _bootstrap._gcd_import(name[level:], package, level)\n",
      "  File \"/home/codespace/anaconda3/lib/python3.12/site-packages/bottleneck/__init__.py\", line 7, in <module>\n",
      "    from .move import (move_argmax, move_argmin, move_max, move_mean, move_median,\n"
     ]
    },
    {
     "ename": "ImportError",
     "evalue": "\nA module that was compiled using NumPy 1.x cannot be run in\nNumPy 2.2.4 as it may crash. To support both 1.x and 2.x\nversions of NumPy, modules must be compiled with NumPy 2.0.\nSome module may need to rebuild instead e.g. with 'pybind11>=2.12'.\n\nIf you are a user of the module, the easiest solution will be to\ndowngrade to 'numpy<2' or try to upgrade the affected module.\nWe expect that some modules will need time to support NumPy 2.\n\n",
     "output_type": "error",
     "traceback": [
      "\u001b[31m---------------------------------------------------------------------------\u001b[39m",
      "\u001b[31mImportError\u001b[39m                               Traceback (most recent call last)",
      "\u001b[36mFile \u001b[39m\u001b[32m~/.local/lib/python3.12/site-packages/numpy/core/_multiarray_umath.py:44\u001b[39m, in \u001b[36m__getattr__\u001b[39m\u001b[34m(attr_name)\u001b[39m\n\u001b[32m     39\u001b[39m     \u001b[38;5;66;03m# Also print the message (with traceback).  This is because old versions\u001b[39;00m\n\u001b[32m     40\u001b[39m     \u001b[38;5;66;03m# of NumPy unfortunately set up the import to replace (and hide) the\u001b[39;00m\n\u001b[32m     41\u001b[39m     \u001b[38;5;66;03m# error.  The traceback shouldn't be needed, but e.g. pytest plugins\u001b[39;00m\n\u001b[32m     42\u001b[39m     \u001b[38;5;66;03m# seem to swallow it and we should be failing anyway...\u001b[39;00m\n\u001b[32m     43\u001b[39m     sys.stderr.write(msg + tb_msg)\n\u001b[32m---> \u001b[39m\u001b[32m44\u001b[39m     \u001b[38;5;28;01mraise\u001b[39;00m \u001b[38;5;167;01mImportError\u001b[39;00m(msg)\n\u001b[32m     46\u001b[39m ret = \u001b[38;5;28mgetattr\u001b[39m(_multiarray_umath, attr_name, \u001b[38;5;28;01mNone\u001b[39;00m)\n\u001b[32m     47\u001b[39m \u001b[38;5;28;01mif\u001b[39;00m ret \u001b[38;5;129;01mis\u001b[39;00m \u001b[38;5;28;01mNone\u001b[39;00m:\n",
      "\u001b[31mImportError\u001b[39m: \nA module that was compiled using NumPy 1.x cannot be run in\nNumPy 2.2.4 as it may crash. To support both 1.x and 2.x\nversions of NumPy, modules must be compiled with NumPy 2.0.\nSome module may need to rebuild instead e.g. with 'pybind11>=2.12'.\n\nIf you are a user of the module, the easiest solution will be to\ndowngrade to 'numpy<2' or try to upgrade the affected module.\nWe expect that some modules will need time to support NumPy 2.\n\n"
     ]
    }
   ],
   "source": [
    "import pandas as pd"
   ]
  },
  {
   "cell_type": "code",
   "execution_count": null,
   "id": "c8e8d42a-ee09-4572-8a77-67fc00ce3789",
   "metadata": {},
   "outputs": [],
   "source": [
    "!pip uninstall pyarrow\n",
    "Y"
   ]
  },
  {
   "cell_type": "code",
   "execution_count": 4,
   "id": "df1a0059-0bd7-432d-a64c-8ddc360178a6",
   "metadata": {},
   "outputs": [
    {
     "data": {
      "text/plain": [
       "'2.2.3'"
      ]
     },
     "execution_count": 4,
     "metadata": {},
     "output_type": "execute_result"
    }
   ],
   "source": [
    "pd.__version__"
   ]
  },
  {
   "cell_type": "code",
   "execution_count": null,
   "id": "c09650a5-6489-485b-829f-aee23bdb584e",
   "metadata": {},
   "outputs": [],
   "source": []
  },
  {
   "cell_type": "code",
   "execution_count": 5,
   "id": "92542233-884d-491d-9ae4-307bc0885c40",
   "metadata": {},
   "outputs": [
    {
     "name": "stdout",
     "output_type": "stream",
     "text": [
      "Requirement already satisfied: pyarrow in /home/codespace/anaconda3/lib/python3.12/site-packages (16.1.0)\n",
      "Requirement already satisfied: numpy>=1.16.6 in /home/codespace/.local/lib/python3.12/site-packages (from pyarrow) (2.2.4)\n"
     ]
    }
   ],
   "source": [
    "!pip install pyarrow\n",
    "\n",
    "!pip"
   ]
  },
  {
   "cell_type": "code",
   "execution_count": 6,
   "id": "d11eedc4-a22c-46bc-8a4a-fd35687f0117",
   "metadata": {},
   "outputs": [
    {
     "name": "stderr",
     "output_type": "stream",
     "text": [
      "\n",
      "A module that was compiled using NumPy 1.x cannot be run in\n",
      "NumPy 2.2.4 as it may crash. To support both 1.x and 2.x\n",
      "versions of NumPy, modules must be compiled with NumPy 2.0.\n",
      "Some module may need to rebuild instead e.g. with 'pybind11>=2.12'.\n",
      "\n",
      "If you are a user of the module, the easiest solution will be to\n",
      "downgrade to 'numpy<2' or try to upgrade the affected module.\n",
      "We expect that some modules will need time to support NumPy 2.\n",
      "\n",
      "Traceback (most recent call last):  File \"<frozen runpy>\", line 198, in _run_module_as_main\n",
      "  File \"<frozen runpy>\", line 88, in _run_code\n",
      "  File \"/home/codespace/.local/lib/python3.12/site-packages/ipykernel_launcher.py\", line 18, in <module>\n",
      "    app.launch_new_instance()\n",
      "  File \"/home/codespace/.local/lib/python3.12/site-packages/traitlets/config/application.py\", line 1075, in launch_instance\n",
      "    app.start()\n",
      "  File \"/home/codespace/.local/lib/python3.12/site-packages/ipykernel/kernelapp.py\", line 739, in start\n",
      "    self.io_loop.start()\n",
      "  File \"/home/codespace/.local/lib/python3.12/site-packages/tornado/platform/asyncio.py\", line 205, in start\n",
      "    self.asyncio_loop.run_forever()\n",
      "  File \"/home/codespace/anaconda3/lib/python3.12/asyncio/base_events.py\", line 641, in run_forever\n",
      "    self._run_once()\n",
      "  File \"/home/codespace/anaconda3/lib/python3.12/asyncio/base_events.py\", line 1986, in _run_once\n",
      "    handle._run()\n",
      "  File \"/home/codespace/anaconda3/lib/python3.12/asyncio/events.py\", line 88, in _run\n",
      "    self._context.run(self._callback, *self._args)\n",
      "  File \"/home/codespace/.local/lib/python3.12/site-packages/ipykernel/kernelbase.py\", line 545, in dispatch_queue\n",
      "    await self.process_one()\n",
      "  File \"/home/codespace/.local/lib/python3.12/site-packages/ipykernel/kernelbase.py\", line 534, in process_one\n",
      "    await dispatch(*args)\n",
      "  File \"/home/codespace/.local/lib/python3.12/site-packages/ipykernel/kernelbase.py\", line 437, in dispatch_shell\n",
      "    await result\n",
      "  File \"/home/codespace/.local/lib/python3.12/site-packages/ipykernel/ipkernel.py\", line 362, in execute_request\n",
      "    await super().execute_request(stream, ident, parent)\n",
      "  File \"/home/codespace/.local/lib/python3.12/site-packages/ipykernel/kernelbase.py\", line 778, in execute_request\n",
      "    reply_content = await reply_content\n",
      "  File \"/home/codespace/.local/lib/python3.12/site-packages/ipykernel/ipkernel.py\", line 449, in do_execute\n",
      "    res = shell.run_cell(\n",
      "  File \"/home/codespace/.local/lib/python3.12/site-packages/ipykernel/zmqshell.py\", line 549, in run_cell\n",
      "    return super().run_cell(*args, **kwargs)\n",
      "  File \"/home/codespace/.local/lib/python3.12/site-packages/IPython/core/interactiveshell.py\", line 3047, in run_cell\n",
      "    result = self._run_cell(\n",
      "  File \"/home/codespace/.local/lib/python3.12/site-packages/IPython/core/interactiveshell.py\", line 3102, in _run_cell\n",
      "    result = runner(coro)\n",
      "  File \"/home/codespace/.local/lib/python3.12/site-packages/IPython/core/async_helpers.py\", line 128, in _pseudo_sync_runner\n",
      "    coro.send(None)\n",
      "  File \"/home/codespace/.local/lib/python3.12/site-packages/IPython/core/interactiveshell.py\", line 3306, in run_cell_async\n",
      "    has_raised = await self.run_ast_nodes(code_ast.body, cell_name,\n",
      "  File \"/home/codespace/.local/lib/python3.12/site-packages/IPython/core/interactiveshell.py\", line 3489, in run_ast_nodes\n",
      "    if await self.run_code(code, result, async_=asy):\n",
      "  File \"/home/codespace/.local/lib/python3.12/site-packages/IPython/core/interactiveshell.py\", line 3549, in run_code\n",
      "    exec(code_obj, self.user_global_ns, self.user_ns)\n",
      "  File \"/tmp/ipykernel_15184/308287444.py\", line 1, in <module>\n",
      "    df = pd.read_parquet('https://d37ci6vzurychx.cloudfront.net/trip-data/yellow_tripdata_2025-01.parquet')\n",
      "  File \"/home/codespace/.local/lib/python3.12/site-packages/pandas/io/parquet.py\", line 651, in read_parquet\n",
      "    impl = get_engine(engine)\n",
      "  File \"/home/codespace/.local/lib/python3.12/site-packages/pandas/io/parquet.py\", line 63, in get_engine\n",
      "    return engine_class()\n",
      "  File \"/home/codespace/.local/lib/python3.12/site-packages/pandas/io/parquet.py\", line 163, in __init__\n",
      "    import_optional_dependency(\n",
      "  File \"/home/codespace/.local/lib/python3.12/site-packages/pandas/compat/_optional.py\", line 135, in import_optional_dependency\n",
      "    module = importlib.import_module(name)\n",
      "  File \"/home/codespace/anaconda3/lib/python3.12/importlib/__init__.py\", line 90, in import_module\n",
      "    return _bootstrap._gcd_import(name[level:], package, level)\n",
      "  File \"/home/codespace/anaconda3/lib/python3.12/site-packages/pyarrow/__init__.py\", line 65, in <module>\n",
      "    import pyarrow.lib as _lib\n"
     ]
    },
    {
     "ename": "ImportError",
     "evalue": "\nA module that was compiled using NumPy 1.x cannot be run in\nNumPy 2.2.4 as it may crash. To support both 1.x and 2.x\nversions of NumPy, modules must be compiled with NumPy 2.0.\nSome module may need to rebuild instead e.g. with 'pybind11>=2.12'.\n\nIf you are a user of the module, the easiest solution will be to\ndowngrade to 'numpy<2' or try to upgrade the affected module.\nWe expect that some modules will need time to support NumPy 2.\n\n",
     "output_type": "error",
     "traceback": [
      "\u001b[31m---------------------------------------------------------------------------\u001b[39m",
      "\u001b[31mImportError\u001b[39m                               Traceback (most recent call last)",
      "\u001b[36mFile \u001b[39m\u001b[32m~/.local/lib/python3.12/site-packages/numpy/core/_multiarray_umath.py:44\u001b[39m, in \u001b[36m__getattr__\u001b[39m\u001b[34m(attr_name)\u001b[39m\n\u001b[32m     39\u001b[39m     \u001b[38;5;66;03m# Also print the message (with traceback).  This is because old versions\u001b[39;00m\n\u001b[32m     40\u001b[39m     \u001b[38;5;66;03m# of NumPy unfortunately set up the import to replace (and hide) the\u001b[39;00m\n\u001b[32m     41\u001b[39m     \u001b[38;5;66;03m# error.  The traceback shouldn't be needed, but e.g. pytest plugins\u001b[39;00m\n\u001b[32m     42\u001b[39m     \u001b[38;5;66;03m# seem to swallow it and we should be failing anyway...\u001b[39;00m\n\u001b[32m     43\u001b[39m     sys.stderr.write(msg + tb_msg)\n\u001b[32m---> \u001b[39m\u001b[32m44\u001b[39m     \u001b[38;5;28;01mraise\u001b[39;00m \u001b[38;5;167;01mImportError\u001b[39;00m(msg)\n\u001b[32m     46\u001b[39m ret = \u001b[38;5;28mgetattr\u001b[39m(_multiarray_umath, attr_name, \u001b[38;5;28;01mNone\u001b[39;00m)\n\u001b[32m     47\u001b[39m \u001b[38;5;28;01mif\u001b[39;00m ret \u001b[38;5;129;01mis\u001b[39;00m \u001b[38;5;28;01mNone\u001b[39;00m:\n",
      "\u001b[31mImportError\u001b[39m: \nA module that was compiled using NumPy 1.x cannot be run in\nNumPy 2.2.4 as it may crash. To support both 1.x and 2.x\nversions of NumPy, modules must be compiled with NumPy 2.0.\nSome module may need to rebuild instead e.g. with 'pybind11>=2.12'.\n\nIf you are a user of the module, the easiest solution will be to\ndowngrade to 'numpy<2' or try to upgrade the affected module.\nWe expect that some modules will need time to support NumPy 2.\n\n"
     ]
    },
    {
     "ename": "ImportError",
     "evalue": "Unable to find a usable engine; tried using: 'pyarrow', 'fastparquet'.\nA suitable version of pyarrow or fastparquet is required for parquet support.\nTrying to import the above resulted in these errors:\n - Missing optional dependency 'pyarrow'. pyarrow is required for parquet support. Use pip or conda to install pyarrow.\n - Missing optional dependency 'fastparquet'. fastparquet is required for parquet support. Use pip or conda to install fastparquet.",
     "output_type": "error",
     "traceback": [
      "\u001b[31m---------------------------------------------------------------------------\u001b[39m",
      "\u001b[31mImportError\u001b[39m                               Traceback (most recent call last)",
      "\u001b[36mCell\u001b[39m\u001b[36m \u001b[39m\u001b[32mIn[6]\u001b[39m\u001b[32m, line 1\u001b[39m\n\u001b[32m----> \u001b[39m\u001b[32m1\u001b[39m df = \u001b[43mpd\u001b[49m\u001b[43m.\u001b[49m\u001b[43mread_parquet\u001b[49m\u001b[43m(\u001b[49m\u001b[33;43m'\u001b[39;49m\u001b[33;43mhttps://d37ci6vzurychx.cloudfront.net/trip-data/yellow_tripdata_2025-01.parquet\u001b[39;49m\u001b[33;43m'\u001b[39;49m\u001b[43m)\u001b[49m\n",
      "\u001b[36mFile \u001b[39m\u001b[32m~/.local/lib/python3.12/site-packages/pandas/io/parquet.py:651\u001b[39m, in \u001b[36mread_parquet\u001b[39m\u001b[34m(path, engine, columns, storage_options, use_nullable_dtypes, dtype_backend, filesystem, filters, **kwargs)\u001b[39m\n\u001b[32m    498\u001b[39m \u001b[38;5;129m@doc\u001b[39m(storage_options=_shared_docs[\u001b[33m\"\u001b[39m\u001b[33mstorage_options\u001b[39m\u001b[33m\"\u001b[39m])\n\u001b[32m    499\u001b[39m \u001b[38;5;28;01mdef\u001b[39;00m\u001b[38;5;250m \u001b[39m\u001b[34mread_parquet\u001b[39m(\n\u001b[32m    500\u001b[39m     path: FilePath | ReadBuffer[\u001b[38;5;28mbytes\u001b[39m],\n\u001b[32m   (...)\u001b[39m\u001b[32m    508\u001b[39m     **kwargs,\n\u001b[32m    509\u001b[39m ) -> DataFrame:\n\u001b[32m    510\u001b[39m \u001b[38;5;250m    \u001b[39m\u001b[33;03m\"\"\"\u001b[39;00m\n\u001b[32m    511\u001b[39m \u001b[33;03m    Load a parquet object from the file path, returning a DataFrame.\u001b[39;00m\n\u001b[32m    512\u001b[39m \n\u001b[32m   (...)\u001b[39m\u001b[32m    648\u001b[39m \u001b[33;03m    1    4    9\u001b[39;00m\n\u001b[32m    649\u001b[39m \u001b[33;03m    \"\"\"\u001b[39;00m\n\u001b[32m--> \u001b[39m\u001b[32m651\u001b[39m     impl = \u001b[43mget_engine\u001b[49m\u001b[43m(\u001b[49m\u001b[43mengine\u001b[49m\u001b[43m)\u001b[49m\n\u001b[32m    653\u001b[39m     \u001b[38;5;28;01mif\u001b[39;00m use_nullable_dtypes \u001b[38;5;129;01mis\u001b[39;00m \u001b[38;5;129;01mnot\u001b[39;00m lib.no_default:\n\u001b[32m    654\u001b[39m         msg = (\n\u001b[32m    655\u001b[39m             \u001b[33m\"\u001b[39m\u001b[33mThe argument \u001b[39m\u001b[33m'\u001b[39m\u001b[33muse_nullable_dtypes\u001b[39m\u001b[33m'\u001b[39m\u001b[33m is deprecated and will be removed \u001b[39m\u001b[33m\"\u001b[39m\n\u001b[32m    656\u001b[39m             \u001b[33m\"\u001b[39m\u001b[33min a future version.\u001b[39m\u001b[33m\"\u001b[39m\n\u001b[32m    657\u001b[39m         )\n",
      "\u001b[36mFile \u001b[39m\u001b[32m~/.local/lib/python3.12/site-packages/pandas/io/parquet.py:67\u001b[39m, in \u001b[36mget_engine\u001b[39m\u001b[34m(engine)\u001b[39m\n\u001b[32m     64\u001b[39m         \u001b[38;5;28;01mexcept\u001b[39;00m \u001b[38;5;167;01mImportError\u001b[39;00m \u001b[38;5;28;01mas\u001b[39;00m err:\n\u001b[32m     65\u001b[39m             error_msgs += \u001b[33m\"\u001b[39m\u001b[38;5;130;01m\\n\u001b[39;00m\u001b[33m - \u001b[39m\u001b[33m\"\u001b[39m + \u001b[38;5;28mstr\u001b[39m(err)\n\u001b[32m---> \u001b[39m\u001b[32m67\u001b[39m     \u001b[38;5;28;01mraise\u001b[39;00m \u001b[38;5;167;01mImportError\u001b[39;00m(\n\u001b[32m     68\u001b[39m         \u001b[33m\"\u001b[39m\u001b[33mUnable to find a usable engine; \u001b[39m\u001b[33m\"\u001b[39m\n\u001b[32m     69\u001b[39m         \u001b[33m\"\u001b[39m\u001b[33mtried using: \u001b[39m\u001b[33m'\u001b[39m\u001b[33mpyarrow\u001b[39m\u001b[33m'\u001b[39m\u001b[33m, \u001b[39m\u001b[33m'\u001b[39m\u001b[33mfastparquet\u001b[39m\u001b[33m'\u001b[39m\u001b[33m.\u001b[39m\u001b[38;5;130;01m\\n\u001b[39;00m\u001b[33m\"\u001b[39m\n\u001b[32m     70\u001b[39m         \u001b[33m\"\u001b[39m\u001b[33mA suitable version of \u001b[39m\u001b[33m\"\u001b[39m\n\u001b[32m     71\u001b[39m         \u001b[33m\"\u001b[39m\u001b[33mpyarrow or fastparquet is required for parquet \u001b[39m\u001b[33m\"\u001b[39m\n\u001b[32m     72\u001b[39m         \u001b[33m\"\u001b[39m\u001b[33msupport.\u001b[39m\u001b[38;5;130;01m\\n\u001b[39;00m\u001b[33m\"\u001b[39m\n\u001b[32m     73\u001b[39m         \u001b[33m\"\u001b[39m\u001b[33mTrying to import the above resulted in these errors:\u001b[39m\u001b[33m\"\u001b[39m\n\u001b[32m     74\u001b[39m         \u001b[33mf\u001b[39m\u001b[33m\"\u001b[39m\u001b[38;5;132;01m{\u001b[39;00merror_msgs\u001b[38;5;132;01m}\u001b[39;00m\u001b[33m\"\u001b[39m\n\u001b[32m     75\u001b[39m     )\n\u001b[32m     77\u001b[39m \u001b[38;5;28;01mif\u001b[39;00m engine == \u001b[33m\"\u001b[39m\u001b[33mpyarrow\u001b[39m\u001b[33m\"\u001b[39m:\n\u001b[32m     78\u001b[39m     \u001b[38;5;28;01mreturn\u001b[39;00m PyArrowImpl()\n",
      "\u001b[31mImportError\u001b[39m: Unable to find a usable engine; tried using: 'pyarrow', 'fastparquet'.\nA suitable version of pyarrow or fastparquet is required for parquet support.\nTrying to import the above resulted in these errors:\n - Missing optional dependency 'pyarrow'. pyarrow is required for parquet support. Use pip or conda to install pyarrow.\n - Missing optional dependency 'fastparquet'. fastparquet is required for parquet support. Use pip or conda to install fastparquet."
     ]
    }
   ],
   "source": [
    "df = pd.read_parquet('https://d37ci6vzurychx.cloudfront.net/trip-data/yellow_tripdata_2025-01.parquet')"
   ]
  },
  {
   "cell_type": "code",
   "execution_count": null,
   "id": "92b0fe31-9b27-4f50-8a28-a39e772c84ab",
   "metadata": {},
   "outputs": [],
   "source": []
  }
 ],
 "metadata": {
  "kernelspec": {
   "display_name": "Python 3 (ipykernel)",
   "language": "python",
   "name": "python3"
  },
  "language_info": {
   "codemirror_mode": {
    "name": "ipython",
    "version": 3
   },
   "file_extension": ".py",
   "mimetype": "text/x-python",
   "name": "python",
   "nbconvert_exporter": "python",
   "pygments_lexer": "ipython3",
   "version": "3.12.2"
  }
 },
 "nbformat": 4,
 "nbformat_minor": 5
}
